Top-level error
---------------
KeyError: 500

The above exception was the direct cause of the following exception:

Traceback (most recent call last):
  File "/home/magranro/code/newseye/pimlico/src/python/pimlico/core/modules/execute.py", line 300, in execute_modules
    end_status = executor(module, debug=debug, force_rerun=force_rerun).execute()
  File "/home/magranro/code/newseye/pimlico/src/python/pimlico/core/modules/map/__init__.py", line 223, in execute
    for (archive, doc_name), next_output in mapper.map_documents():
  File "/home/magranro/code/newseye/pimlico/src/python/pimlico/core/modules/map/__init__.py", line 362, in map_documents
    cause=error, debugging_info=debugging), error)
  File "/home/magranro/code/newseye/pimlico/lib/test_env/lib/python3.5/site-packages/future/utils/__init__.py", line 403, in raise_from
    exec(execstr, myglobals, mylocals)
  File "<string>", line 1, in <module>
pimlico.core.modules.execute.ModuleExecutionError: error in worker process: 500

The above exception was the direct cause of the following exception:

Traceback (most recent call last):
  File "/home/magranro/code/newseye/pimlico/src/python/pimlico/core/modules/execute.py", line 313, in execute_modules
    e
  File "/home/magranro/code/newseye/pimlico/lib/test_env/lib/python3.5/site-packages/future/utils/__init__.py", line 403, in raise_from
    exec(execstr, myglobals, mylocals)
  File "<string>", line 1, in <module>
pimlico.core.modules.execute.ModuleExecutionError: error in worker process: 500


Details of error
----------------
pimlico.core.modules.execute.ModuleExecutionError: error in worker process: 500

## Further debugging info ##
Uncaught exception in executor. Traceback from original exception: 
  File "/home/magranro/code/newseye/pimlico/src/python/pimlico/core/modules/execute.py", line 300, in execute_modules
    end_status = executor(module, debug=debug, force_rerun=force_rerun).execute()
  File "/home/magranro/code/newseye/pimlico/src/python/pimlico/core/modules/map/__init__.py", line 223, in execute
    for (archive, doc_name), next_output in mapper.map_documents():
  File "/home/magranro/code/newseye/pimlico/src/python/pimlico/core/modules/map/__init__.py", line 362, in map_documents
    cause=error, debugging_info=debugging), error)
  File "/home/magranro/code/newseye/pimlico/lib/test_env/lib/python3.5/site-packages/future/utils/__init__.py", line 403, in raise_from
    exec(execstr, myglobals, mylocals)
  File "<string>", line 1, in <module>

